Workbook

Sheet Benchmarks
B1: Newsweek Digital Ads — Performance Benchmarks
B2: Companion to Newsweek_Digital_Ads_Specs_Master.xlsx. One row per sellable placement; targets normalised out of the specs master's free-text Benchmarks column into numeric, comparable fields.
B3: PLACEMENT | I3: TARGET | M3: MEASUREMENT | O3: GOVERNANCE
B4: Ad Product | C4: Ad Size | D4: Website(s) | E4: Location | F4: Section | G4: Canonical Format | H4: Benchmark Key | I4: CTR target | J4: Viewability target | K4: VCR target | L4: Engagement target | M4: Viewability measurable? | N4: Measurement & delivery notes | O4: Targets set? | P4: Review flag | Q4: Source (verbatim, specs master) | R4: Last reviewed
B5: STANDARD BANNERS
B6: Medium Rectangle | C6: 300x250 | D6: newsweek.com | E6: Article Pages | F6: STANDARD BANNERS | G6: Display | H6: =IF($B6="","",$F6&" · "&$B6&" · "&$C6) -> STANDARD BANNERS · Medium Rectangle · 300x250 | I6: 0.001 | J6: 0.7 | M6: Yes | N6: Standard GPT slot; measures organically in GAM Active View. | O6: =IF(COUNT($I6:$L6)=0,"⚠ none",IF(COUNT($I6:$L6)=1,"partial","yes")) -> yes | Q6: 0.10% CTR / 70% Viewability | R6: 46267
B7: Half Page | C7: 300x600 | D7: newsweek.com | E7: Article Pages | F7: STANDARD BANNERS | G7: Display | H7: =IF($B7="","",$F7&" · "&$B7&" · "&$C7) -> STANDARD BANNERS · Half Page · 300x600 | I7: 0.001 | J7: 0.7 | M7: Yes | N7: Standard GPT slot; measures organically in GAM Active View. | O7: =IF(COUNT($I7:$L7)=0,"⚠ none",IF(COUNT($I7:$L7)=1,"partial","yes")) -> yes | Q7: 0.10% CTR / 70% Viewability | R7: 46267
B8: Leaderboard | C8: 728x90 | D8: newsweek.com | E8: Article Pages | F8: STANDARD BANNERS | G8: Display | H8: =IF($B8="","",$F8&" · "&$B8&" · "&$C8) -> STANDARD BANNERS · Leaderboard · 728x90 | I8: 0.001 | J8: 0.7 | M8: Yes | N8: Standard GPT slot; measures organically in GAM Active View. | O8: =IF(COUNT($I8:$L8)=0,"⚠ none",IF(COUNT($I8:$L8)=1,"partial","yes")) -> yes | Q8: 0.10% CTR / 70% Viewability | R8: 46267
B9: Billboard ad | C9: 970x250 | D9: newsweek.com | E9: Article Pages | F9: STANDARD BANNERS | G9: Display | H9: =IF($B9="","",$F9&" · "&$B9&" · "&$C9) -> STANDARD BANNERS · Billboard ad · 970x250 | I9: 0.001 | J9: 0.7 | M9: Yes | N9: Standard GPT slot; measures organically in GAM Active View. | O9: =IF(COUNT($I9:$L9)=0,"⚠ none",IF(COUNT($I9:$L9)=1,"partial","yes")) -> yes | Q9: 0.10% CTR / 70% Viewability | R9: 46267
B10: Smartphone Banner | C10: 300x50 / 320x50 | D10: newsweek.com | E10: Article Pages | F10: STANDARD BANNERS | G10: Display | H10: =IF($B10="","",$F10&" · "&$B10&" · "&$C10) -> STANDARD BANNERS · Smartphone Banner · 300x50 / 320x50 | I10: 0.001 | J10: 0.7 | M10: Yes | N10: Standard GPT slot; measures organically in GAM Active View. | O10: =IF(COUNT($I10:$L10)=0,"⚠ none",IF(COUNT($I10:$L10)=1,"partial","yes")) -> yes | Q10: 0.10% CTR / 70% Viewability | R10: 46267
B11: Insights Premium Spotlight | C11: 1200x675 / Logo | D11: newsweek.com | E11: Homepage | F11: STANDARD BANNERS | G11: Display | H11: =IF($B11="","",$F11&" · "&$B11&" · "&$C11) -> STANDARD BANNERS · Insights Premium Spotlight · 1200x675 / Logo | I11: 0.005 | M11: Yes | N11: Native-style unit; renders in-frame. | O11: =IF(COUNT($I11:$L11)=0,"⚠ none",IF(COUNT($I11:$L11)=1,"partial","yes")) -> partial | P11: No viewability target set - every other standard banner carries 70%. Confirm intended. | Q11: 0.50% CTR | R11: 46267
B12: VIDEO PRE-ROLL
B13: Pre Roll | C13: 16:9 | D13: newsweek.com | E13: Article Pages | F13: VIDEO PRE-ROLL | G13: Video | H13: =IF($B13="","",$F13&" · "&$B13&" · "&$C13) -> VIDEO PRE-ROLL · Pre Roll · 16:9 | I13: 0.006 | J13: 0.7 | K13: 0.7 | M13: Yes | N13: In-player video; VCR from GAM video metrics. | O13: =IF(COUNT($I13:$L13)=0,"⚠ none",IF(COUNT($I13:$L13)=1,"partial","yes")) -> yes | P13: 0.60% CTR is high for pre-roll - confirm this is the sold target, not a stretch goal. | Q13: 0.60% CTR / 70% Viewability / 70% VCR | R13: 46267
B14: CENTERSTAGE
B15: Desktop Ribbon | C15: 3840x350 | D15: newsweek.com | E15: Homepage | F15: CENTERSTAGE | G15: Centerstage | H15: =IF($B15="","",$F15&" · "&$B15&" · "&$C15) -> CENTERSTAGE · Desktop Ribbon · 3840x350 | I15: 0.01 | J15: 0.7 | M15: Yes | N15: In-frame takeover render; measured 58-67% viewable in production. | O15: =IF(COUNT($I15:$L15)=0,"⚠ none",IF(COUNT($I15:$L15)=1,"partial","yes")) -> yes | Q15: 1% CTR / 70% Viewability | R15: 46267
B16: Desktop Large Banner | C16: 3200x700 | D16: newsweek.com | E16: Homepage | F16: CENTERSTAGE | G16: Centerstage | H16: =IF($B16="","",$F16&" · "&$B16&" · "&$C16) -> CENTERSTAGE · Desktop Large Banner · 3200x700 | I16: 0.001 | J16: 0.7 | M16: Yes | N16: In-frame takeover render. | O16: =IF(COUNT($I16:$L16)=0,"⚠ none",IF(COUNT($I16:$L16)=1,"partial","yes")) -> yes | P16: 0.10% CTR vs 1% on Ribbon / Mobile Sticky in the same family - 10x gap, confirm. | Q16: 0.10% CTR / 70% Viewability | R16: 46267
B17: Mobile Sticky | C17: 900x350 | D17: newsweek.com | E17: Homepage | F17: CENTERSTAGE | G17: Centerstage | H17: =IF($B17="","",$F17&" · "&$B17&" · "&$C17) -> CENTERSTAGE · Mobile Sticky · 900x350 | I17: 0.01 | J17: 0.7 | M17: Yes | N17: In-frame takeover render. | O17: =IF(COUNT($I17:$L17)=0,"⚠ none",IF(COUNT($I17:$L17)=1,"partial","yes")) -> yes | Q17: 1% CTR / 70% Viewability | R17: 46267
B18: Mobile Large Banner | C18: 1200x900 | D18: newsweek.com | E18: Homepage | F18: CENTERSTAGE | G18: Centerstage | H18: =IF($B18="","",$F18&" · "&$B18&" · "&$C18) -> CENTERSTAGE · Mobile Large Banner · 1200x900 | I18: 0.001 | J18: 0.7 | M18: Yes | N18: In-frame takeover render. | O18: =IF(COUNT($I18:$L18)=0,"⚠ none",IF(COUNT($I18:$L18)=1,"partial","yes")) -> yes | P18: 0.10% CTR vs 1% on Ribbon / Mobile Sticky in the same family - 10x gap, confirm. | Q18: 0.10% CTR / 70% Viewability | R18: 46267
B19: Video Takeover Desktop | C19: 16:9 | D19: newsweek.com | E19: Homepage | F19: CENTERSTAGE | G19: Centerstage | H19: =IF($B19="","",$F19&" · "&$B19&" · "&$C19) -> CENTERSTAGE · Video Takeover Desktop · 16:9 | I19: 0.001 | J19: 0.7 | M19: Yes | N19: Video takeover; start/complete tracked. | O19: =IF(COUNT($I19:$L19)=0,"⚠ none",IF(COUNT($I19:$L19)=1,"partial","yes")) -> yes | P19: Video unit with no VCR target - add one to grade completion. | Q19: 0.10% CTR / 70% Viewability | R19: 46267
B20: Video Takeover Mobile | C20: 9:16 | D20: newsweek.com | E20: Homepage | F20: CENTERSTAGE | G20: Centerstage | H20: =IF($B20="","",$F20&" · "&$B20&" · "&$C20) -> CENTERSTAGE · Video Takeover Mobile · 9:16 | I20: 0.001 | J20: 0.7 | M20: Yes | N20: Video takeover; start/complete tracked. | O20: =IF(COUNT($I20:$L20)=0,"⚠ none",IF(COUNT($I20:$L20)=1,"partial","yes")) -> yes | P20: Video unit with no VCR target - add one to grade completion. | Q20: 0.10% CTR / 70% Viewability | R20: 46267
B21: FITO DISPLAY (FIRST IMPRESSION TAKE OVER)
B22: Desktop Top Banner | C22: 970x250 | D22: newsweek.com | E22: Article Pages | F22: FITO DISPLAY | G22: FITO | H22: =IF($B22="","",$F22&" · "&$B22&" · "&$C22) -> FITO DISPLAY · Desktop Top Banner · 970x250 | I22: 0.005 | M22: Yes - verify | N22: Served via carrier-slot placement injection; confirm Active View reads real geometry on the live creative. | O22: =IF(COUNT($I22:$L22)=0,"⚠ none",IF(COUNT($I22:$L22)=1,"partial","yes")) -> partial | P22: No viewability target set - sibling FITO rows all carry 70%. | Q22: 0.50% CTR (stored as a raw number in the specs master) | R22: 46267
B23: Mobile Sticky | C23: 1300x350 or 320x50 | D23: newsweek.com | E23: Article Pages | F23: FITO DISPLAY | G23: FITO | H23: =IF($B23="","",$F23&" · "&$B23&" · "&$C23) -> FITO DISPLAY · Mobile Sticky · 1300x350 or 320x50 | I23: 0.001 | J23: 0.7 | M23: Yes | N23: Standard sticky render. | O23: =IF(COUNT($I23:$L23)=0,"⚠ none",IF(COUNT($I23:$L23)=1,"partial","yes")) -> yes | Q23: 0.10% CTR / 70% Viewability | R23: 46267
B24: Fluid 250 (in-article, optional) | C24: 2560x250 | D24: newsweek.com | E24: Article Pages | F24: FITO DISPLAY | G24: Display | H24: =IF($B24="","",$F24&" · "&$B24&" · "&$C24) -> FITO DISPLAY · Fluid 250 (in-article, optional) · 2560x250 | J24: 0.7 | M24: Yes | N24: Fluid in-article render. | O24: =IF(COUNT($I24:$L24)=0,"⚠ none",IF(COUNT($I24:$L24)=1,"partial","yes")) -> partial | P24: No CTR target set. | Q24: 70% Viewability | R24: 46267
B25: In-Article (Desktop) | C25: 3200x500, 1600x250 or 970x250 | D25: newsweek.com | E25: Article Pages | F25: FITO DISPLAY | G25: Display | H25: =IF($B25="","",$F25&" · "&$B25&" · "&$C25) -> FITO DISPLAY · In-Article (Desktop) · 3200x500, 1600x250 or 970x250 | I25: 0.001 | J25: 0.7 | M25: Yes | N25: Standard in-article slot. | O25: =IF(COUNT($I25:$L25)=0,"⚠ none",IF(COUNT($I25:$L25)=1,"partial","yes")) -> yes | Q25: 0.10% CTR / 70% Viewability | R25: 46267
B26: Mobile Top Banner | C26: 1200x900 or 300x250 | D26: newsweek.com | E26: Article Pages | F26: FITO DISPLAY | G26: FITO | H26: =IF($B26="","",$F26&" · "&$B26&" · "&$C26) -> FITO DISPLAY · Mobile Top Banner · 1200x900 or 300x250 | I26: 0.005 | M26: Yes - verify | N26: Served via carrier-slot placement injection; confirm Active View reads real geometry on the live creative. | O26: =IF(COUNT($I26:$L26)=0,"⚠ none",IF(COUNT($I26:$L26)=1,"partial","yes")) -> partial | P26: No viewability target set - sibling FITO rows all carry 70%. | Q26: 0.50% CTR (stored as a raw number in the specs master) | R26: 46267
B27: Medium Rectangle | C27: 300x250 | D27: newsweek.com | E27: Article Pages | F27: FITO DISPLAY | G27: Display | H27: =IF($B27="","",$F27&" · "&$B27&" · "&$C27) -> FITO DISPLAY · Medium Rectangle · 300x250 | I27: 0.001 | J27: 0.7 | M27: Yes | N27: Standard GPT slot. | O27: =IF(COUNT($I27:$L27)=0,"⚠ none",IF(COUNT($I27:$L27)=1,"partial","yes")) -> yes | Q27: 0.10% CTR / 70% Viewability | R27: 46267
B28: Leaderboard | C28: 728x90 | D28: newsweek.com | E28: Article Pages | F28: FITO DISPLAY | G28: Display | H28: =IF($B28="","",$F28&" · "&$B28&" · "&$C28) -> FITO DISPLAY · Leaderboard · 728x90 | I28: 0.001 | J28: 0.7 | M28: Yes | N28: Standard GPT slot. | O28: =IF(COUNT($I28:$L28)=0,"⚠ none",IF(COUNT($I28:$L28)=1,"partial","yes")) -> yes | Q28: 0.10% CTR / 70% Viewability | R28: 46267
B29: FITO VIDEO (FIRST IMPRESSION TAKE OVER)
B30: Desktop Top Banner | C30: 2310x500, 3200x500 or 970x250 | D30: newsweek.com | E30: Article Pages | F30: FITO VIDEO | G30: FITO | H30: =IF($B30="","",$F30&" · "&$B30&" · "&$C30) -> FITO VIDEO · Desktop Top Banner · 2310x500, 3200x500 or 970x250 | I30: 0.006 | J30: 0.7 | M30: Yes - verify | N30: In-banner video via injected carrier slot; confirm Active View geometry. | O30: =IF(COUNT($I30:$L30)=0,"⚠ none",IF(COUNT($I30:$L30)=1,"partial","yes")) -> yes | P30: In-banner video with no VCR target - add one to grade completion. | Q30: 0.60% CTR / 70% Viewability | R30: 46267
B31: Mobile Leaderboard (Sticky) | C31: 1300x350 or 320x50 | D31: newsweek.com | E31: Article Pages | F31: FITO VIDEO | G31: FITO | H31: =IF($B31="","",$F31&" · "&$B31&" · "&$C31) -> FITO VIDEO · Mobile Leaderboard (Sticky) · 1300x350 or 320x50 | I31: 0.006 | J31: 0.7 | M31: Yes | N31: Standard sticky render. | O31: =IF(COUNT($I31:$L31)=0,"⚠ none",IF(COUNT($I31:$L31)=1,"partial","yes")) -> yes | Q31: 0.60% CTR / 70% Viewability | R31: 46267
B32: Mobile Top Banner | C32: 1200x900 or 300x250 | D32: newsweek.com | E32: Article Pages | F32: FITO VIDEO | G32: FITO | H32: =IF($B32="","",$F32&" · "&$B32&" · "&$C32) -> FITO VIDEO · Mobile Top Banner · 1200x900 or 300x250 | I32: 0.001 | J32: 0.7 | M32: Yes - verify | N32: Served via carrier-slot placement injection; confirm Active View geometry. | O32: =IF(COUNT($I32:$L32)=0,"⚠ none",IF(COUNT($I32:$L32)=1,"partial","yes")) -> yes | P32: 0.10% CTR here vs 0.60% on the other FITO Video units - confirm. | Q32: 0.10% CTR / 70% Viewability | R32: 46267
B33: Fluid 250 (in-article, optional) | C33: 2560x250 | D33: newsweek.com | E33: Article Pages | F33: FITO VIDEO | G33: Display | H33: =IF($B33="","",$F33&" · "&$B33&" · "&$C33) -> FITO VIDEO · Fluid 250 (in-article, optional) · 2560x250 | J33: 0.7 | M33: Yes | N33: Fluid in-article render. | O33: =IF(COUNT($I33:$L33)=0,"⚠ none",IF(COUNT($I33:$L33)=1,"partial","yes")) -> partial | P33: No CTR target set. | Q33: 70% Viewability | R33: 46267
B34: In-Article (Desktop) | C34: 3200x500, 1600x250 or 970x250 | D34: newsweek.com | E34: Article Pages | F34: FITO VIDEO | G34: Display | H34: =IF($B34="","",$F34&" · "&$B34&" · "&$C34) -> FITO VIDEO · In-Article (Desktop) · 3200x500, 1600x250 or 970x250 | I34: 0.001 | J34: 0.7 | M34: Yes | N34: Standard in-article slot. | O34: =IF(COUNT($I34:$L34)=0,"⚠ none",IF(COUNT($I34:$L34)=1,"partial","yes")) -> yes | Q34: 0.10% CTR / 70% Viewability | R34: 46267
B35: Medium Rectangle (mobile) | C35: 300x250 | D35: newsweek.com | E35: Article Pages | F35: FITO VIDEO | G35: Display | H35: =IF($B35="","",$F35&" · "&$B35&" · "&$C35) -> FITO VIDEO · Medium Rectangle (mobile) · 300x250 | I35: 0.001 | J35: 0.7 | M35: Yes | N35: Standard GPT slot. | O35: =IF(COUNT($I35:$L35)=0,"⚠ none",IF(COUNT($I35:$L35)=1,"partial","yes")) -> yes | Q35: 0.10% CTR / 70% Viewability | R35: 46267
B36: Desktop Leaderboard (Sticky) | C36: 728x90 | D36: newsweek.com | E36: Article Pages | F36: FITO VIDEO | G36: Display | H36: =IF($B36="","",$F36&" · "&$B36&" · "&$C36) -> FITO VIDEO · Desktop Leaderboard (Sticky) · 728x90 | I36: 0.001 | J36: 0.7 | M36: Yes | N36: Standard GPT slot. | O36: =IF(COUNT($I36:$L36)=0,"⚠ none",IF(COUNT($I36:$L36)=1,"partial","yes")) -> yes | Q36: 0.10% CTR / 70% Viewability | R36: 46267
B37: Video Takeover | C37: Horizontal 16:9 | D37: newsweek.com | E37: Homepage | F37: FITO VIDEO | G37: Centerstage | H37: =IF($B37="","",$F37&" · "&$B37&" · "&$C37) -> FITO VIDEO · Video Takeover · Horizontal 16:9 | I37: 0.001 | J37: 0.7 | M37: Yes | N37: Video takeover; start/complete tracked. | O37: =IF(COUNT($I37:$L37)=0,"⚠ none",IF(COUNT($I37:$L37)=1,"partial","yes")) -> yes | P37: Video unit with no VCR target - add one to grade completion. | Q37: 0.10% CTR / 70% Viewability | R37: 46267
B38: HIGH IMPACT
B39: Fluid 250 | C39: 2560x600 | D39: newsweek.com | E39: Article Pages | F39: HIGH IMPACT | G39: Display | H39: =IF($B39="","",$F39&" · "&$B39&" · "&$C39) -> HIGH IMPACT · Fluid 250 · 2560x600 | I39: 0.0015 | J39: 0.7 | K39: 0.4 | L39: 0.65 | M39: Yes | N39: Engagement rate is vendor-reported, not a GAM metric - pull it from the high-impact partner's report. | O39: =IF(COUNT($I39:$L39)=0,"⚠ none",IF(COUNT($I39:$L39)=1,"partial","yes")) -> yes | Q39: 0.15% CTR, 40% VCR, 65% Engagement, 70% Viewability | R39: 46267
B40: Fluid 400 | C40: 2560x600 | D40: newsweek.com | E40: Article Pages | F40: HIGH IMPACT | G40: Display | H40: =IF($B40="","",$F40&" · "&$B40&" · "&$C40) -> HIGH IMPACT · Fluid 400 · 2560x600 | I40: 0.002 | J40: 0.5 | K40: 0.45 | L40: 0.6 | M40: Yes | N40: Engagement rate is vendor-reported, not a GAM metric. | O40: =IF(COUNT($I40:$L40)=0,"⚠ none",IF(COUNT($I40:$L40)=1,"partial","yes")) -> yes | Q40: 0.20% CTR, 45% VCR, 60% Engagement, 50% Viewability | R40: 46267
...

Sheet Performance Tracker
B1: Performance Tracker — actual vs benchmark
B2: Fill the amber cells. Everything else is a formula: rates, the benchmark pulled from the Benchmarks sheet, the gap, and the verdict.
B3: LINE ITEM | F3: DELIVERY (paste from GAM) | L3: ACTUAL | O3: TARGET (auto) | R3: GAP vs target (pp) | U3: VERDICT
B4: Line item / campaign | C4: Benchmark Key (pick from list) | D4: Flight start | E4: Flight end | F4: Impressions | G4: Clicks | H4: Measurable impr. | I4: Viewable impr. | J4: Video starts | K4: Video completes | L4: CTR | M4: Viewability | N4: VCR | O4: CTR | P4: Viewability | Q4: VCR | R4: CTR | S4: Viewability | T4: VCR | U4: CTR | V4: Viewability | W4: VCR | X4: Overall
B5: EXAMPLE — Infiniti Newsmakers (delete this row) | C5: STANDARD BANNERS · Medium Rectangle · 300x250 | D5: 46235 | E5: 46265 | F5: 1250000 | G5: 1500 | H5: 1180000 | I5: 796500 | L5: =IFERROR($G5/$F5,"") -> 0.0012 | M5: =IFERROR($I5/$H5,"") -> 0.675 | N5: =IFERROR($K5/$J5,"") | O5: =IF($C5="","",IFERROR(IF(INDEX(Benchmarks!$I$6:$I$71,MATCH($C5,Benchmarks!$H$6:$H$71,0))="","",INDEX(Benchmarks!$I$6:$I$71,MATCH($C5,Benchmarks!$H$6:$H$71,0))),"")) -> 0.001 | P5: =IF($C5="","",IFERROR(IF(INDEX(Benchmarks!$J$6:$J$71,MATCH($C5,Benchmarks!$H$6:$H$71,0))="","",INDEX(Benchmarks!$J$6:$J$71,MATCH($C5,Benchmarks!$H$6:$H$71,0))),"")) -> 0.7 | Q5: =IF($C5="","",IFERROR(IF(INDEX(Benchmarks!$K$6:$K$71,MATCH($C5,Benchmarks!$H$6:$H$71,0))="","",INDEX(Benchmarks!$K$6:$K$71,MATCH($C5,Benchmarks!$H$6:$H$71,0))),"")) | R5: =IF(OR($L5="",$O5=""),"",($L5-$O5)*100) -> 0.02 | S5: =IF(OR($M5="",$P5=""),"",($M5-$P5)*100) -> -2.5 | T5: =IF(OR($N5="",$Q5=""),"",($N5-$Q5)*100) | U5: =IF(OR($L5="",$O5=""),"",IF($F5<Thresholds!$D$7,"THIN",IF($L5>=$O5,"PASS",IF($L5>=$O5*Thresholds!$D$6,"WATCH","MISS")))) -> PASS | V5: =IF(OR($M5="",$P5=""),"",IF($F5<Thresholds!$D$7,"THIN",IF($M5>=$P5,"PASS",IF($M5>=$P5*Thresholds!$D$6,"WATCH","MISS")))) -> WATCH | W5: =IF(OR($N5="",$Q5=""),"",IF($F5<Thresholds!$D$7,"THIN",IF($N5>=$Q5,"PASS",IF($N5>=$Q5*Thresholds!$D$6,"WATCH","MISS")))) | X5: =IF(COUNTIF($U5:$W5,"MISS")>0,"MISS",IF(COUNTIF($U5:$W5,"WATCH")>0,"WATCH",IF(COUNTIF($U5:$W5,"PASS")>0,"PASS",IF(COUNTIF($U5:$W5,"THIN")>0,"THIN","")))) -> WATCH
L6: =IFERROR($G6/$F6,"") | M6: =IFERROR($I6/$H6,"") | N6: =IFERROR($K6/$J6,"") | O6: =IF($C6="","",IFERROR(IF(INDEX(Benchmarks!$I$6:$I$71,MATCH($C6,Benchmarks!$H$6:$H$71,0))="","",INDEX(Benchmarks!$I$6:$I$71,MATCH($C6,Benchmarks!$H$6:$H$71,0))),"")) | P6: =IF($C6="","",IFERROR(IF(INDEX(Benchmarks!$J$6:$J$71,MATCH($C6,Benchmarks!$H$6:$H$71,0))="","",INDEX(Benchmarks!$J$6:$J$71,MATCH($C6,Benchmarks!$H$6:$H$71,0))),"")) | Q6: =IF($C6="","",IFERROR(IF(INDEX(Benchmarks!$K$6:$K$71,MATCH($C6,Benchmarks!$H$6:$H$71,0))="","",INDEX(Benchmarks!$K$6:$K$71,MATCH($C6,Benchmarks!$H$6:$H$71,0))),"")) | R6: =IF(OR($L6="",$O6=""),"",($L6-$O6)*100) | S6: =IF(OR($M6="",$P6=""),"",($M6-$P6)*100) | T6: =IF(OR($N6="",$Q6=""),"",($N6-$Q6)*100) | U6: =IF(OR($L6="",$O6=""),"",IF($F6<Thresholds!$D$7,"THIN",IF($L6>=$O6,"PASS",IF($L6>=$O6*Thresholds!$D$6,"WATCH","MISS")))) | V6: =IF(OR($M6="",$P6=""),"",IF($F6<Thresholds!$D$7,"THIN",IF($M6>=$P6,"PASS",IF($M6>=$P6*Thresholds!$D$6,"WATCH","MISS")))) | W6: =IF(OR($N6="",$Q6=""),"",IF($F6<Thresholds!$D$7,"THIN",IF($N6>=$Q6,"PASS",IF($N6>=$Q6*Thresholds!$D$6,"WATCH","MISS")))) | X6: =IF(COUNTIF($U6:$W6,"MISS")>0,"MISS",IF(COUNTIF($U6:$W6,"WATCH")>0,"WATCH",IF(COUNTIF($U6:$W6,"PASS")>0,"PASS",IF(COUNTIF($U6:$W6,"THIN")>0,"THIN",""))))
L7: =IFERROR($G7/$F7,"") | M7: =IFERROR($I7/$H7,"") | N7: =IFERROR($K7/$J7,"") | O7: =IF($C7="","",IFERROR(IF(INDEX(Benchmarks!$I$6:$I$71,MATCH($C7,Benchmarks!$H$6:$H$71,0))="","",INDEX(Benchmarks!$I$6:$I$71,MATCH($C7,Benchmarks!$H$6:$H$71,0))),"")) | P7: =IF($C7="","",IFERROR(IF(INDEX(Benchmarks!$J$6:$J$71,MATCH($C7,Benchmarks!$H$6:$H$71,0))="","",INDEX(Benchmarks!$J$6:$J$71,MATCH($C7,Benchmarks!$H$6:$H$71,0))),"")) | Q7: =IF($C7="","",IFERROR(IF(INDEX(Benchmarks!$K$6:$K$71,MATCH($C7,Benchmarks!$H$6:$H$71,0))="","",INDEX(Benchmarks!$K$6:$K$71,MATCH($C7,Benchmarks!$H$6:$H$71,0))),"")) | R7: =IF(OR($L7="",$O7=""),"",($L7-$O7)*100) | S7: =IF(OR($M7="",$P7=""),"",($M7-$P7)*100) | T7: =IF(OR($N7="",$Q7=""),"",($N7-$Q7)*100) | U7: =IF(OR($L7="",$O7=""),"",IF($F7<Thresholds!$D$7,"THIN",IF($L7>=$O7,"PASS",IF($L7>=$O7*Thresholds!$D$6,"WATCH","MISS")))) | V7: =IF(OR($M7="",$P7=""),"",IF($F7<Thresholds!$D$7,"THIN",IF($M7>=$P7,"PASS",IF($M7>=$P7*Thresholds!$D$6,"WATCH","MISS")))) | W7: =IF(OR($N7="",$Q7=""),"",IF($F7<Thresholds!$D$7,"THIN",IF($N7>=$Q7,"PASS",IF($N7>=$Q7*Thresholds!$D$6,"WATCH","MISS")))) | X7: =IF(COUNTIF($U7:$W7,"MISS")>0,"MISS",IF(COUNTIF($U7:$W7,"WATCH")>0,"WATCH",IF(COUNTIF($U7:$W7,"PASS")>0,"PASS",IF(COUNTIF($U7:$W7,"THIN")>0,"THIN",""))))
L8: =IFERROR($G8/$F8,"") | M8: =IFERROR($I8/$H8,"") | N8: =IFERROR($K8/$J8,"") | O8: =IF($C8="","",IFERROR(IF(INDEX(Benchmarks!$I$6:$I$71,MATCH($C8,Benchmarks!$H$6:$H$71,0))="","",INDEX(Benchmarks!$I$6:$I$71,MATCH($C8,Benchmarks!$H$6:$H$71,0))),"")) | P8: =IF($C8="","",IFERROR(IF(INDEX(Benchmarks!$J$6:$J$71,MATCH($C8,Benchmarks!$H$6:$H$71,0))="","",INDEX(Benchmarks!$J$6:$J$71,MATCH($C8,Benchmarks!$H$6:$H$71,0))),"")) | Q8: =IF($C8="","",IFERROR(IF(INDEX(Benchmarks!$K$6:$K$71,MATCH($C8,Benchmarks!$H$6:$H$71,0))="","",INDEX(Benchmarks!$K$6:$K$71,MATCH($C8,Benchmarks!$H$6:$H$71,0))),"")) | R8: =IF(OR($L8="",$O8=""),"",($L8-$O8)*100) | S8: =IF(OR($M8="",$P8=""),"",($M8-$P8)*100) | T8: =IF(OR($N8="",$Q8=""),"",($N8-$Q8)*100) | U8: =IF(OR($L8="",$O8=""),"",IF($F8<Thresholds!$D$7,"THIN",IF($L8>=$O8,"PASS",IF($L8>=$O8*Thresholds!$D$6,"WATCH","MISS")))) | V8: =IF(OR($M8="",$P8=""),"",IF($F8<Thresholds!$D$7,"THIN",IF($M8>=$P8,"PASS",IF($M8>=$P8*Thresholds!$D$6,"WATCH","MISS")))) | W8: =IF(OR($N8="",$Q8=""),"",IF($F8<Thresholds!$D$7,"THIN",IF($N8>=$Q8,"PASS",IF($N8>=$Q8*Thresholds!$D$6,"WATCH","MISS")))) | X8: =IF(COUNTIF($U8:$W8,"MISS")>0,"MISS",IF(COUNTIF($U8:$W8,"WATCH")>0,"WATCH",IF(COUNTIF($U8:$W8,"PASS")>0,"PASS",IF(COUNTIF($U8:$W8,"THIN")>0,"THIN",""))))
L9: =IFERROR($G9/$F9,"") | M9: =IFERROR($I9/$H9,"") | N9: =IFERROR($K9/$J9,"") | O9: =IF($C9="","",IFERROR(IF(INDEX(Benchmarks!$I$6:$I$71,MATCH($C9,Benchmarks!$H$6:$H$71,0))="","",INDEX(Benchmarks!$I$6:$I$71,MATCH($C9,Benchmarks!$H$6:$H$71,0))),"")) | P9: =IF($C9="","",IFERROR(IF(INDEX(Benchmarks!$J$6:$J$71,MATCH($C9,Benchmarks!$H$6:$H$71,0))="","",INDEX(Benchmarks!$J$6:$J$71,MATCH($C9,Benchmarks!$H$6:$H$71,0))),"")) | Q9: =IF($C9="","",IFERROR(IF(INDEX(Benchmarks!$K$6:$K$71,MATCH($C9,Benchmarks!$H$6:$H$71,0))="","",INDEX(Benchmarks!$K$6:$K$71,MATCH($C9,Benchmarks!$H$6:$H$71,0))),"")) | R9: =IF(OR($L9="",$O9=""),"",($L9-$O9)*100) | S9: =IF(OR($M9="",$P9=""),"",($M9-$P9)*100) | T9: =IF(OR($N9="",$Q9=""),"",($N9-$Q9)*100) | U9: =IF(OR($L9="",$O9=""),"",IF($F9<Thresholds!$D$7,"THIN",IF($L9>=$O9,"PASS",IF($L9>=$O9*Thresholds!$D$6,"WATCH","MISS")))) | V9: =IF(OR($M9="",$P9=""),"",IF($F9<Thresholds!$D$7,"THIN",IF($M9>=$P9,"PASS",IF($M9>=$P9*Thresholds!$D$6,"WATCH","MISS")))) | W9: =IF(OR($N9="",$Q9=""),"",IF($F9<Thresholds!$D$7,"THIN",IF($N9>=$Q9,"PASS",IF($N9>=$Q9*Thresholds!$D$6,"WATCH","MISS")))) | X9: =IF(COUNTIF($U9:$W9,"MISS")>0,"MISS",IF(COUNTIF($U9:$W9,"WATCH")>0,"WATCH",IF(COUNTIF($U9:$W9,"PASS")>0,"PASS",IF(COUNTIF($U9:$W9,"THIN")>0,"THIN",""))))
L10: =IFERROR($G10/$F10,"") | M10: =IFERROR($I10/$H10,"") | N10: =IFERROR($K10/$J10,"") | O10: =IF($C10="","",IFERROR(IF(INDEX(Benchmarks!$I$6:$I$71,MATCH($C10,Benchmarks!$H$6:$H$71,0))="","",INDEX(Benchmarks!$I$6:$I$71,MATCH($C10,Benchmarks!$H$6:$H$71,0))),"")) | P10: =IF($C10="","",IFERROR(IF(INDEX(Benchmarks!$J$6:$J$71,MATCH($C10,Benchmarks!$H$6:$H$71,0))="","",INDEX(Benchmarks!$J$6:$J$71,MATCH($C10,Benchmarks!$H$6:$H$71,0))),"")) | Q10: =IF($C10="","",IFERROR(IF(INDEX(Benchmarks!$K$6:$K$71,MATCH($C10,Benchmarks!$H$6:$H$71,0))="","",INDEX(Benchmarks!$K$6:$K$71,MATCH($C10,Benchmarks!$H$6:$H$71,0))),"")) | R10: =IF(OR($L10="",$O10=""),"",($L10-$O10)*100) | S10: =IF(OR($M10="",$P10=""),"",($M10-$P10)*100) | T10: =IF(OR($N10="",$Q10=""),"",($N10-$Q10)*100) | U10: =IF(OR($L10="",$O10=""),"",IF($F10<Thresholds!$D$7,"THIN",IF($L10>=$O10,"PASS",IF($L10>=$O10*Thresholds!$D$6,"WATCH","MISS")))) | V10: =IF(OR($M10="",$P10=""),"",IF($F10<Thresholds!$D$7,"THIN",IF($M10>=$P10,"PASS",IF($M10>=$P10*Thresholds!$D$6,"WATCH","MISS")))) | W10: =IF(OR($N10="",$Q10=""),"",IF($F10<Thresholds!$D$7,"THIN",IF($N10>=$Q10,"PASS",IF($N10>=$Q10*Thresholds!$D$6,"WATCH","MISS")))) | X10: =IF(COUNTIF($U10:$W10,"MISS")>0,"MISS",IF(COUNTIF($U10:$W10,"WATCH")>0,"WATCH",IF(COUNTIF($U10:$W10,"PASS")>0,"PASS",IF(COUNTIF($U10:$W10,"THIN")>0,"THIN",""))))
L11: =IFERROR($G11/$F11,"") | M11: =IFERROR($I11/$H11,"") | N11: =IFERROR($K11/$J11,"") | O11: =IF($C11="","",IFERROR(IF(INDEX(Benchmarks!$I$6:$I$71,MATCH($C11,Benchmarks!$H$6:$H$71,0))="","",INDEX(Benchmarks!$I$6:$I$71,MATCH($C11,Benchmarks!$H$6:$H$71,0))),"")) | P11: =IF($C11="","",IFERROR(IF(INDEX(Benchmarks!$J$6:$J$71,MATCH($C11,Benchmarks!$H$6:$H$71,0))="","",INDEX(Benchmarks!$J$6:$J$71,MATCH($C11,Benchmarks!$H$6:$H$71,0))),"")) | Q11: =IF($C11="","",IFERROR(IF(INDEX(Benchmarks!$K$6:$K$71,MATCH($C11,Benchmarks!$H$6:$H$71,0))="","",INDEX(Benchmarks!$K$6:$K$71,MATCH($C11,Benchmarks!$H$6:$H$71,0))),"")) | R11: =IF(OR($L11="",$O11=""),"",($L11-$O11)*100) | S11: =IF(OR($M11="",$P11=""),"",($M11-$P11)*100) | T11: =IF(OR($N11="",$Q11=""),"",($N11-$Q11)*100) | U11: =IF(OR($L11="",$O11=""),"",IF($F11<Thresholds!$D$7,"THIN",IF($L11>=$O11,"PASS",IF($L11>=$O11*Thresholds!$D$6,"WATCH","MISS")))) | V11: =IF(OR($M11="",$P11=""),"",IF($F11<Thresholds!$D$7,"THIN",IF($M11>=$P11,"PASS",IF($M11>=$P11*Thresholds!$D$6,"WATCH","MISS")))) | W11: =IF(OR($N11="",$Q11=""),"",IF($F11<Thresholds!$D$7,"THIN",IF($N11>=$Q11,"PASS",IF($N11>=$Q11*Thresholds!$D$6,"WATCH","MISS")))) | X11: =IF(COUNTIF($U11:$W11,"MISS")>0,"MISS",IF(COUNTIF($U11:$W11,"WATCH")>0,"WATCH",IF(COUNTIF($U11:$W11,"PASS")>0,"PASS",IF(COUNTIF($U11:$W11,"THIN")>0,"THIN",""))))
L12: =IFERROR($G12/$F12,"") | M12: =IFERROR($I12/$H12,"") | N12: =IFERROR($K12/$J12,"") | O12: =IF($C12="","",IFERROR(IF(INDEX(Benchmarks!$I$6:$I$71,MATCH($C12,Benchmarks!$H$6:$H$71,0))="","",INDEX(Benchmarks!$I$6:$I$71,MATCH($C12,Benchmarks!$H$6:$H$71,0))),"")) | P12: =IF($C12="","",IFERROR(IF(INDEX(Benchmarks!$J$6:$J$71,MATCH($C12,Benchmarks!$H$6:$H$71,0))="","",INDEX(Benchmarks!$J$6:$J$71,MATCH($C12,Benchmarks!$H$6:$H$71,0))),"")) | Q12: =IF($C12="","",IFERROR(IF(INDEX(Benchmarks!$K$6:$K$71,MATCH($C12,Benchmarks!$H$6:$H$71,0))="","",INDEX(Benchmarks!$K$6:$K$71,MATCH($C12,Benchmarks!$H$6:$H$71,0))),"")) | R12: =IF(OR($L12="",$O12=""),"",($L12-$O12)*100) | S12: =IF(OR($M12="",$P12=""),"",($M12-$P12)*100) | T12: =IF(OR($N12="",$Q12=""),"",($N12-$Q12)*100) | U12: =IF(OR($L12="",$O12=""),"",IF($F12<Thresholds!$D$7,"THIN",IF($L12>=$O12,"PASS",IF($L12>=$O12*Thresholds!$D$6,"WATCH","MISS")))) | V12: =IF(OR($M12="",$P12=""),"",IF($F12<Thresholds!$D$7,"THIN",IF($M12>=$P12,"PASS",IF($M12>=$P12*Thresholds!$D$6,"WATCH","MISS")))) | W12: =IF(OR($N12="",$Q12=""),"",IF($F12<Thresholds!$D$7,"THIN",IF($N12>=$Q12,"PASS",IF($N12>=$Q12*Thresholds!$D$6,"WATCH","MISS")))) | X12: =IF(COUNTIF($U12:$W12,"MISS")>0,"MISS",IF(COUNTIF($U12:$W12,"WATCH")>0,"WATCH",IF(COUNTIF($U12:$W12,"PASS")>0,"PASS",IF(COUNTIF($U12:$W12,"THIN")>0,"THIN",""))))
L13: =IFERROR($G13/$F13,"") | M13: =IFERROR($I13/$H13,"") | N13: =IFERROR($K13/$J13,"") | O13: =IF($C13="","",IFERROR(IF(INDEX(Benchmarks!$I$6:$I$71,MATCH($C13,Benchmarks!$H$6:$H$71,0))="","",INDEX(Benchmarks!$I$6:$I$71,MATCH($C13,Benchmarks!$H$6:$H$71,0))),"")) | P13: =IF($C13="","",IFERROR(IF(INDEX(Benchmarks!$J$6:$J$71,MATCH($C13,Benchmarks!$H$6:$H$71,0))="","",INDEX(Benchmarks!$J$6:$J$71,MATCH($C13,Benchmarks!$H$6:$H$71,0))),"")) | Q13: =IF($C13="","",IFERROR(IF(INDEX(Benchmarks!$K$6:$K$71,MATCH($C13,Benchmarks!$H$6:$H$71,0))="","",INDEX(Benchmarks!$K$6:$K$71,MATCH($C13,Benchmarks!$H$6:$H$71,0))),"")) | R13: =IF(OR($L13="",$O13=""),"",($L13-$O13)*100) | S13: =IF(OR($M13="",$P13=""),"",($M13-$P13)*100) | T13: =IF(OR($N13="",$Q13=""),"",($N13-$Q13)*100) | U13: =IF(OR($L13="",$O13=""),"",IF($F13<Thresholds!$D$7,"THIN",IF($L13>=$O13,"PASS",IF($L13>=$O13*Thresholds!$D$6,"WATCH","MISS")))) | V13: =IF(OR($M13="",$P13=""),"",IF($F13<Thresholds!$D$7,"THIN",IF($M13>=$P13,"PASS",IF($M13>=$P13*Thresholds!$D$6,"WATCH","MISS")))) | W13: =IF(OR($N13="",$Q13=""),"",IF($F13<Thresholds!$D$7,"THIN",IF($N13>=$Q13,"PASS",IF($N13>=$Q13*Thresholds!$D$6,"WATCH","MISS")))) | X13: =IF(COUNTIF($U13:$W13,"MISS")>0,"MISS",IF(COUNTIF($U13:$W13,"WATCH")>0,"WATCH",IF(COUNTIF($U13:$W13,"PASS")>0,"PASS",IF(COUNTIF($U13:$W13,"THIN")>0,"THIN",""))))
L14: =IFERROR($G14/$F14,"") | M14: =IFERROR($I14/$H14,"") | N14: =IFERROR($K14/$J14,"") | O14: =IF($C14="","",IFERROR(IF(INDEX(Benchmarks!$I$6:$I$71,MATCH($C14,Benchmarks!$H$6:$H$71,0))="","",INDEX(Benchmarks!$I$6:$I$71,MATCH($C14,Benchmarks!$H$6:$H$71,0))),"")) | P14: =IF($C14="","",IFERROR(IF(INDEX(Benchmarks!$J$6:$J$71,MATCH($C14,Benchmarks!$H$6:$H$71,0))="","",INDEX(Benchmarks!$J$6:$J$71,MATCH($C14,Benchmarks!$H$6:$H$71,0))),"")) | Q14: =IF($C14="","",IFERROR(IF(INDEX(Benchmarks!$K$6:$K$71,MATCH($C14,Benchmarks!$H$6:$H$71,0))="","",INDEX(Benchmarks!$K$6:$K$71,MATCH($C14,Benchmarks!$H$6:$H$71,0))),"")) | R14: =IF(OR($L14="",$O14=""),"",($L14-$O14)*100) | S14: =IF(OR($M14="",$P14=""),"",($M14-$P14)*100) | T14: =IF(OR($N14="",$Q14=""),"",($N14-$Q14)*100) | U14: =IF(OR($L14="",$O14=""),"",IF($F14<Thresholds!$D$7,"THIN",IF($L14>=$O14,"PASS",IF($L14>=$O14*Thresholds!$D$6,"WATCH","MISS")))) | V14: =IF(OR($M14="",$P14=""),"",IF($F14<Thresholds!$D$7,"THIN",IF($M14>=$P14,"PASS",IF($M14>=$P14*Thresholds!$D$6,"WATCH","MISS")))) | W14: =IF(OR($N14="",$Q14=""),"",IF($F14<Thresholds!$D$7,"THIN",IF($N14>=$Q14,"PASS",IF($N14>=$Q14*Thresholds!$D$6,"WATCH","MISS")))) | X14: =IF(COUNTIF($U14:$W14,"MISS")>0,"MISS",IF(COUNTIF($U14:$W14,"WATCH")>0,"WATCH",IF(COUNTIF($U14:$W14,"PASS")>0,"PASS",IF(COUNTIF($U14:$W14,"THIN")>0,"THIN",""))))
L15: =IFERROR($G15/$F15,"") | M15: =IFERROR($I15/$H15,"") | N15: =IFERROR($K15/$J15,"") | O15: =IF($C15="","",IFERROR(IF(INDEX(Benchmarks!$I$6:$I$71,MATCH($C15,Benchmarks!$H$6:$H$71,0))="","",INDEX(Benchmarks!$I$6:$I$71,MATCH($C15,Benchmarks!$H$6:$H$71,0))),"")) | P15: =IF($C15="","",IFERROR(IF(INDEX(Benchmarks!$J$6:$J$71,MATCH($C15,Benchmarks!$H$6:$H$71,0))="","",INDEX(Benchmarks!$J$6:$J$71,MATCH($C15,Benchmarks!$H$6:$H$71,0))),"")) | Q15: =IF($C15="","",IFERROR(IF(INDEX(Benchmarks!$K$6:$K$71,MATCH($C15,Benchmarks!$H$6:$H$71,0))="","",INDEX(Benchmarks!$K$6:$K$71,MATCH($C15,Benchmarks!$H$6:$H$71,0))),"")) | R15: =IF(OR($L15="",$O15=""),"",($L15-$O15)*100) | S15: =IF(OR($M15="",$P15=""),"",($M15-$P15)*100) | T15: =IF(OR($N15="",$Q15=""),"",($N15-$Q15)*100) | U15: =IF(OR($L15="",$O15=""),"",IF($F15<Thresholds!$D$7,"THIN",IF($L15>=$O15,"PASS",IF($L15>=$O15*Thresholds!$D$6,"WATCH","MISS")))) | V15: =IF(OR($M15="",$P15=""),"",IF($F15<Thresholds!$D$7,"THIN",IF($M15>=$P15,"PASS",IF($M15>=$P15*Thresholds!$D$6,"WATCH","MISS")))) | W15: =IF(OR($N15="",$Q15=""),"",IF($F15<Thresholds!$D$7,"THIN",IF($N15>=$Q15,"PASS",IF($N15>=$Q15*Thresholds!$D$6,"WATCH","MISS")))) | X15: =IF(COUNTIF($U15:$W15,"MISS")>0,"MISS",IF(COUNTIF($U15:$W15,"WATCH")>0,"WATCH",IF(COUNTIF($U15:$W15,"PASS")>0,"PASS",IF(COUNTIF($U15:$W15,"THIN")>0,"THIN",""))))
L16: =IFERROR($G16/$F16,"") | M16: =IFERROR($I16/$H16,"") | N16: =IFERROR($K16/$J16,"") | O16: =IF($C16="","",IFERROR(IF(INDEX(Benchmarks!$I$6:$I$71,MATCH($C16,Benchmarks!$H$6:$H$71,0))="","",INDEX(Benchmarks!$I$6:$I$71,MATCH($C16,Benchmarks!$H$6:$H$71,0))),"")) | P16: =IF($C16="","",IFERROR(IF(INDEX(Benchmarks!$J$6:$J$71,MATCH($C16,Benchmarks!$H$6:$H$71,0))="","",INDEX(Benchmarks!$J$6:$J$71,MATCH($C16,Benchmarks!$H$6:$H$71,0))),"")) | Q16: =IF($C16="","",IFERROR(IF(INDEX(Benchmarks!$K$6:$K$71,MATCH($C16,Benchmarks!$H$6:$H$71,0))="","",INDEX(Benchmarks!$K$6:$K$71,MATCH($C16,Benchmarks!$H$6:$H$71,0))),"")) | R16: =IF(OR($L16="",$O16=""),"",($L16-$O16)*100) | S16: =IF(OR($M16="",$P16=""),"",($M16-$P16)*100) | T16: =IF(OR($N16="",$Q16=""),"",($N16-$Q16)*100) | U16: =IF(OR($L16="",$O16=""),"",IF($F16<Thresholds!$D$7,"THIN",IF($L16>=$O16,"PASS",IF($L16>=$O16*Thresholds!$D$6,"WATCH","MISS")))) | V16: =IF(OR($M16="",$P16=""),"",IF($F16<Thresholds!$D$7,"THIN",IF($M16>=$P16,"PASS",IF($M16>=$P16*Thresholds!$D$6,"WATCH","MISS")))) | W16: =IF(OR($N16="",$Q16=""),"",IF($F16<Thresholds!$D$7,"THIN",IF($N16>=$Q16,"PASS",IF($N16>=$Q16*Thresholds!$D$6,"WATCH","MISS")))) | X16: =IF(COUNTIF($U16:$W16,"MISS")>0,"MISS",IF(COUNTIF($U16:$W16,"WATCH")>0,"WATCH",IF(COUNTIF($U16:$W16,"PASS")>0,"PASS",IF(COUNTIF($U16:$W16,"THIN")>0,"THIN",""))))
L17: =IFERROR($G17/$F17,"") | M17: =IFERROR($I17/$H17,"") | N17: =IFERROR($K17/$J17,"") | O17: =IF($C17="","",IFERROR(IF(INDEX(Benchmarks!$I$6:$I$71,MATCH($C17,Benchmarks!$H$6:$H$71,0))="","",INDEX(Benchmarks!$I$6:$I$71,MATCH($C17,Benchmarks!$H$6:$H$71,0))),"")) | P17: =IF($C17="","",IFERROR(IF(INDEX(Benchmarks!$J$6:$J$71,MATCH($C17,Benchmarks!$H$6:$H$71,0))="","",INDEX(Benchmarks!$J$6:$J$71,MATCH($C17,Benchmarks!$H$6:$H$71,0))),"")) | Q17: =IF($C17="","",IFERROR(IF(INDEX(Benchmarks!$K$6:$K$71,MATCH($C17,Benchmarks!$H$6:$H$71,0))="","",INDEX(Benchmarks!$K$6:$K$71,MATCH($C17,Benchmarks!$H$6:$H$71,0))),"")) | R17: =IF(OR($L17="",$O17=""),"",($L17-$O17)*100) | S17: =IF(OR($M17="",$P17=""),"",($M17-$P17)*100) | T17: =IF(OR($N17="",$Q17=""),"",($N17-$Q17)*100) | U17: =IF(OR($L17="",$O17=""),"",IF($F17<Thresholds!$D$7,"THIN",IF($L17>=$O17,"PASS",IF($L17>=$O17*Thresholds!$D$6,"WATCH","MISS")))) | V17: =IF(OR($M17="",$P17=""),"",IF($F17<Thresholds!$D$7,"THIN",IF($M17>=$P17,"PASS",IF($M17>=$P17*Thresholds!$D$6,"WATCH","MISS")))) | W17: =IF(OR($N17="",$Q17=""),"",IF($F17<Thresholds!$D$7,"THIN",IF($N17>=$Q17,"PASS",IF($N17>=$Q17*Thresholds!$D$6,"WATCH","MISS")))) | X17: =IF(COUNTIF($U17:$W17,"MISS")>0,"MISS",IF(COUNTIF($U17:$W17,"WATCH")>0,"WATCH",IF(COUNTIF($U17:$W17,"PASS")>0,"PASS",IF(COUNTIF($U17:$W17,"THIN")>0,"THIN",""))))
... L25: =IFERROR($G25/$F25,"") | M25: =IFERROR($I25/$H25,"") | N25: =IFERROR($K25/$J25,"") | O25: =IF($C25="","",IFERROR(IF(INDEX(Benchmarks!$I$6:$I$71,MATCH($C25,Benchmarks!$H$6:$H$71,0))="","",INDEX(Benchmarks!$I$6:$I$71,MATCH($C25,Benchmarks!$H$6:$H$71,0))),"")) | P25: =IF($C25="","",IFERROR(IF(INDEX(Benchmarks!$J$6:$J$71,MATCH($C25,Benchmarks!$H$6:$H$71,0))="","",INDEX(Benchmarks!$J$6:$J$71,MATCH($C25,Benchmarks!$H$6:$H$71,0))),"")) | Q25: =IF($C25="","",IFERROR(IF(INDEX(Benchmarks!$K$6:$K$71,MATCH($C25,Benchmarks!$H$6:$H$71,0))="","",INDEX(Benchmarks!$K$6:$K$71,MATCH($C25,Benchmarks!$H$6:$H$71,0))),"")) | R25: =IF(OR($L25="",$O25=""),"",($L25-$O25)*100) | S25: =IF(OR($M25="",$P25=""),"",($M25-$P25)*100) | T25: =IF(OR($N25="",$Q25=""),"",($N25-$Q25)*100) | U25: =IF(OR($L25="",$O25=""),"",IF($F25<Thresholds!$D$7,"THIN",IF($L25>=$O25,"PASS",IF($L25>=$O25*Thresholds!$D$6,"WATCH","MISS")))) | V25: =IF(OR($M25="",$P25=""),"",IF($F25<Thresholds!$D$7,"THIN",IF($M25>=$P25,"PASS",IF($M25>=$P25*Thresholds!$D$6,"WATCH","MISS")))) | W25: =IF(OR($N25="",$Q25=""),"",IF($F25<Thresholds!$D$7,"THIN",IF($N25>=$Q25,"PASS",IF($N25>=$Q25*Thresholds!$D$6,"WATCH","MISS")))) | X25: =IF(COUNTIF($U25:$W25,"MISS")>0,"MISS",IF(COUNTIF($U25:$W25,"WATCH")>0,"WATCH",IF(COUNTIF($U25:$W25,"PASS")>0,"PASS",IF(COUNTIF($U25:$W25,"THIN")>0,"THIN",""))))
B27: How to use
B28: • AMBER cells are yours to fill. Grey cells are formulas — don't type over them.
B29: • Column C is a dropdown of every Benchmark Key. Pick one and the targets, gaps and verdicts fill in.
B30: • Paste Impressions / Clicks / Measurable / Viewable straight from a GAM delivery report; leave the video columns blank on display lines.
B31: • Verdicts: PASS at or above target · WATCH within the tolerance band on the Thresholds sheet · MISS below it · THIN when the line hasn't delivered enough impressions for a fair read.
B32: • The row above is an example. Delete it before you share the file.

Sheet Thresholds
B1: Thresholds, banding & rollups
B2: The tolerance levers the Performance Tracker grades against, plus target averages by format and by section.
B4: BANDING LEVERS — edit these
B6: WATCH band — a metric at or above this share of target is WATCH, below it is MISS | D6: 0.9 | H6: 0.90 means: 63% viewability against a 70% target = WATCH; 62% = MISS.
B7: Minimum impressions for a valid read — below this the verdict is THIN | D7: 10000 | H7: Stops a 200-impression line from being graded a MISS on noise.
B8: Benchmark review cadence (months) | D8: 6 | H8: How often this sheet's targets should be re-checked against actual delivery.
B10: TARGET ROLLUP BY CANONICAL FORMAT (auto)
B11: Canonical Format | C11: Placements | D11: Avg CTR target | E11: Avg viewability target | F11: Avg VCR target
B12: Display | C12: =COUNTIF(Benchmarks!$G$6:$G$71,$B12) -> 18 | D12: =IFERROR(AVERAGEIF(Benchmarks!$G$6:$G$71,$B12,Benchmarks!$I$6:$I$71),"—") -> 0.00146875 | E12: =IFERROR(AVERAGEIF(Benchmarks!$G$6:$G$71,$B12,Benchmarks!$J$6:$J$71),"—") -> 0.67352941 | F12: =IFERROR(AVERAGEIF(Benchmarks!$G$6:$G$71,$B12,Benchmarks!$K$6:$K$71),"—") -> 0.4625
B13: Video | C13: =COUNTIF(Benchmarks!$G$6:$G$71,$B13) -> 1 | D13: =IFERROR(AVERAGEIF(Benchmarks!$G$6:$G$71,$B13,Benchmarks!$I$6:$I$71),"—") -> 0.006 | E13: =IFERROR(AVERAGEIF(Benchmarks!$G$6:$G$71,$B13,Benchmarks!$J$6:$J$71),"—") -> 0.7 | F13: =IFERROR(AVERAGEIF(Benchmarks!$G$6:$G$71,$B13,Benchmarks!$K$6:$K$71),"—") -> 0.7
B14: Interstitial | C14: =COUNTIF(Benchmarks!$G$6:$G$71,$B14) -> 2 | D14: =IFERROR(AVERAGEIF(Benchmarks!$G$6:$G$71,$B14,Benchmarks!$I$6:$I$71),"—") -> 0.008 | E14: =IFERROR(AVERAGEIF(Benchmarks!$G$6:$G$71,$B14,Benchmarks!$J$6:$J$71),"—") -> 1 | F14: =IFERROR(AVERAGEIF(Benchmarks!$G$6:$G$71,$B14,Benchmarks!$K$6:$K$71),"—") -> —
B15: Interscroller | C15: =COUNTIF(Benchmarks!$G$6:$G$71,$B15) -> 3 | D15: =IFERROR(AVERAGEIF(Benchmarks!$G$6:$G$71,$B15,Benchmarks!$I$6:$I$71),"—") -> 0.0058333333 | E15: =IFERROR(AVERAGEIF(Benchmarks!$G$6:$G$71,$B15,Benchmarks!$J$6:$J$71),"—") -> 0.55 | F15: =IFERROR(AVERAGEIF(Benchmarks!$G$6:$G$71,$B15,Benchmarks!$K$6:$K$71),"—") -> 0.65
B16: FITO | C16: =COUNTIF(Benchmarks!$G$6:$G$71,$B16) -> 6 | D16: =IFERROR(AVERAGEIF(Benchmarks!$G$6:$G$71,$B16,Benchmarks!$I$6:$I$71),"—") -> 0.004 | E16: =IFERROR(AVERAGEIF(Benchmarks!$G$6:$G$71,$B16,Benchmarks!$J$6:$J$71),"—") -> 0.7 | F16: =IFERROR(AVERAGEIF(Benchmarks!$G$6:$G$71,$B16,Benchmarks!$K$6:$K$71),"—") -> —
B17: Centerstage | C17: =COUNTIF(Benchmarks!$G$6:$G$71,$B17) -> 7 | D17: =IFERROR(AVERAGEIF(Benchmarks!$G$6:$G$71,$B17,Benchmarks!$I$6:$I$71),"—") -> 0.0035714286 | E17: =IFERROR(AVERAGEIF(Benchmarks!$G$6:$G$71,$B17,Benchmarks!$J$6:$J$71),"—") -> 0.7 | F17: =IFERROR(AVERAGEIF(Benchmarks!$G$6:$G$71,$B17,Benchmarks!$K$6:$K$71),"—") -> —
B18: Apple News | C18: =COUNTIF(Benchmarks!$G$6:$G$71,$B18) -> 7 | D18: =IFERROR(AVERAGEIF(Benchmarks!$G$6:$G$71,$B18,Benchmarks!$I$6:$I$71),"—") -> 0.0038571429 | E18: =IFERROR(AVERAGEIF(Benchmarks!$G$6:$G$71,$B18,Benchmarks!$J$6:$J$71),"—") -> 1 | F18: =IFERROR(AVERAGEIF(Benchmarks!$G$6:$G$71,$B18,Benchmarks!$K$6:$K$71),"—") -> —
B19: Social | C19: =COUNTIF(Benchmarks!$G$6:$G$71,$B19) -> 7 | D19: =IFERROR(AVERAGEIF(Benchmarks!$G$6:$G$71,$B19,Benchmarks!$I$6:$I$71),"—") -> 0.007 | E19: =IFERROR(AVERAGEIF(Benchmarks!$G$6:$G$71,$B19,Benchmarks!$J$6:$J$71),"—") -> — | F19: =IFERROR(AVERAGEIF(Benchmarks!$G$6:$G$71,$B19,Benchmarks!$K$6:$K$71),"—") -> —
B20: Newsletter | C20: =COUNTIF(Benchmarks!$G$6:$G$71,$B20) -> 4 | D20: =IFERROR(AVERAGEIF(Benchmarks!$G$6:$G$71,$B20,Benchmarks!$I$6:$I$71),"—") -> 0.0030515 | E20: =IFERROR(AVERAGEIF(Benchmarks!$G$6:$G$71,$B20,Benchmarks!$J$6:$J$71),"—") -> — | F20: =IFERROR(AVERAGEIF(Benchmarks!$G$6:$G$71,$B20,Benchmarks!$K$6:$K$71),"—") -> —
B21: Podcast | C21: =COUNTIF(Benchmarks!$G$6:$G$71,$B21) -> 1 | D21: =IFERROR(AVERAGEIF(Benchmarks!$G$6:$G$71,$B21,Benchmarks!$I$6:$I$71),"—") -> — | E21: =IFERROR(AVERAGEIF(Benchmarks!$G$6:$G$71,$B21,Benchmarks!$J$6:$J$71),"—") -> — | F21: =IFERROR(AVERAGEIF(Benchmarks!$G$6:$G$71,$B21,Benchmarks!$K$6:$K$71),"—") -> —
B23: Averages ignore blanks, so a format whose placements have no viewability target reads '—' rather than 0%.
B25: BENCHMARK KEY LIST — validation source for the Performance Tracker dropdown
B26: Maintenance: add a row to Benchmarks → paste its Benchmark Key here too, or it won't appear in the dropdown.
B28: STANDARD BANNERS · Medium Rectangle · 300x250
B29: STANDARD BANNERS · Half Page · 300x600
B30: STANDARD BANNERS · Leaderboard · 728x90
B31: STANDARD BANNERS · Billboard ad · 970x250
B32: STANDARD BANNERS · Smartphone Banner · 300x50 / 320x50
B33: STANDARD BANNERS · Insights Premium Spotlight · 1200x675 / Logo
B34: VIDEO PRE-ROLL · Pre Roll · 16:9
B35: CENTERSTAGE · Desktop Ribbon · 3840x350
B36: CENTERSTAGE · Desktop Large Banner · 3200x700
... B83: INTERSTITIAL · Desktop · 1600x900

Sheet Definitions
B1: Definitions, caveats & change log
B2: Read this before quoting a number to a client.
B4: METRIC DEFINITIONS
B5: CTR | C5: Clicks ÷ impressions. On social and newsletter this is platform- or ESP-reported and is not directly comparable to on-site CTR.
B6: Viewability | C6: Viewable impressions ÷ measurable impressions, per the MRC standard: 50% of pixels in view for 1 continuous second (2 seconds for video). Not the same as impressions delivered.
B7: Measurable rate | C7: Measurable ÷ total impressions. A low measurable rate makes the viewability number unreliable — check it before grading.
B8: VCR | C8: Video completes ÷ video starts. Grade long-form pre-roll (>:30) against its own line, not the standard video target.
B9: Engagement rate | C9: Vendor-defined interaction rate on high-impact units. It comes from the high-impact partner's report, not GAM — confirm the definition per vendor before promising it.
B10: SIVT / GIVT | C10: Invalid traffic per MRC. Impression-weighted: fraud-classified monitored ads ÷ all monitored ads. Industry bands: green <1%, amber 1–3%, red ≥3%.
B11: Attention Index | C11: DoubleVerify Authentic Attention, indexed to a 100 baseline. Above 100 is better than the benchmark set.
B13: MEASUREMENT CAVEATS — these change what a number means
B14: Breakout / parent-DOM formats | C14: Any creative that renders outside the GPT slot iframe reads ~0% viewable in Active View, and DV agrees, because both instrument the hidden iframe. The tell is healthy CTR with more clicks than 'viewable' impressions. Never sell a vCPM goal on one of these units.
B15: Interscroller (Mobkoi) | C15: Fixed in production by the iframe-mirror creative: same LI went from 0.51% to 56.81% viewable, ~100% measurable. Grade viewability on these units only once the mirror is confirmed live.
B16: Apple News 100% viewability | C16: Apple's guaranteed-view delivery model, reported by Apple. It is not a GAM Active View measurement and should not be averaged with on-site viewability.
B17: Social placements | C17: Meta / LinkedIn / TikTok report their own impressions and clicks. No Active View, no DV. Treat these targets as a separate book.
B18: Newsletter | C18: Email renders have no viewability measurement at all. CTR is ESP-reported and counts differently from ad-server CTR.
B19: DoubleVerify lag | C19: DV's export runs about two days behind. A line that started yesterday will show '—' for Attention and IVT — that's timing, not underperformance.
B20: New line items | C20: A line in its first day or two has no stable rate. The THIN verdict on the tracker exists so nobody escalates on 200 impressions.
B22: WHAT NEEDS A DECISION — carried from the specs master
B23: Video Interscroller viewability | C23: Source reads '0.70% viewability (30 seconds) / 0.40% (60 seconds)'. Entered here as 70% and 40%. Confirm — a 0.70% viewability target isn't plausible.
B24: Newsletter Medium Rectangle CTR | C24: Source reads 0.0006%, roughly 370x below the Long Banner target in the same newsletter. Almost certainly a decimal error.
B25: Apple News and Interstitial CTR | C25: Source reads '0.20 CTR' / '0.30 CTR' / '0.80 CTR' with no % sign. Entered as percentages.
B26: Missing targets | C26: FITO Desktop and Mobile Top Banner have no viewability target while every sibling FITO row carries 70%. Display Interscroller has none either. Fluid 250 has no CTR target.
B27: No benchmark at all | C27: Instagram/Facebook Video, TikTok Display, TikTok Video and Podcast Audio have no target set.
B28: Video units with no VCR | C28: Centerstage Video Takeover (desktop, mobile), FITO Video Desktop Top Banner, LinkedIn Video and Apple News PreRoll all carry a CTR and viewability target but no completion target.
B29: Internal inconsistencies | C29: Centerstage Ribbon and Mobile Sticky target 1% CTR while Large Banner units in the same family target 0.10%. Facebook targets 0.90% against Instagram's 0.10%. Both gaps are worth a sanity check.
B31: CELL LEGEND
B32: Amber fill, blue text | C32: An input. Type here.
B33: Grey fill | C33: A formula. Don't type over it.
B34: Light green fill | C34: Reference data from the specs master.
B35: Red text in 'Review flag' | C35: Needs a human decision before the number is quoted to a client.
B37: CHANGE LOG
B38: 2026-09-02 | C38: Created from Newsweek_Digital_Ads_Specs_Master.xlsx. Free-text Benchmarks column parsed into numeric CTR / viewability / VCR / engagement targets; measurement caveats and review flags added.
